[32mINFO[0m:     [10-01-2024 20:49:08] Set chroma_server_nofile to 65535
[32mINFO[0m:     [10-01-2024 20:49:08] Anonymized telemetry enabled. See                     https://docs.trychroma.com/telemetry for more information.
[36mDEBUG[0m:    [10-01-2024 20:49:08] Starting component System
[36mDEBUG[0m:    [10-01-2024 20:49:08] Starting component OpenTelemetryClient
[36mDEBUG[0m:    [10-01-2024 20:49:08] Starting component SimpleAssignmentPolicy
[36mDEBUG[0m:    [10-01-2024 20:49:08] Starting component SqliteDB
[36mDEBUG[0m:    [10-01-2024 20:49:08] Starting component Posthog
[36mDEBUG[0m:    [10-01-2024 20:49:08] Starting component LocalSegmentManager
[36mDEBUG[0m:    [10-01-2024 20:49:08] Starting component SegmentAPI
[32mINFO[0m:     [10-01-2024 20:49:08] Started server process [[36m54312[0m]
[32mINFO[0m:     [10-01-2024 20:49:08] Waiting for application startup.
[32mINFO[0m:     [10-01-2024 20:49:08] Application startup complete.
[32mINFO[0m:     [10-01-2024 20:49:08] Uvicorn running on [1mhttp://localhost:8000[0m (Press CTRL+C to quit)
[32mINFO[0m:     [10-01-2024 20:49:40] ::1:62591 - "GET / HTTP/1.1" 404
[32mINFO[0m:     [10-01-2024 20:49:40] ::1:62591 - "GET /favicon.ico HTTP/1.1" 404
[32mINFO[0m:     [10-01-2024 20:57:20] ::1:62982 - "POST /api/v1/collections?tenant=default_tenant&database=default_database HTTP/1.1" 200
[31mERROR[0m:    [10-01-2024 20:57:24] Collection my_collection already exists
Traceback (most recent call last):
  File "/Users/andrew/miniconda3/envs/catbook/lib/python3.10/site-packages/anyio/streams/memory.py", line 81, in receive
    return self.receive_nowait()
  File "/Users/andrew/miniconda3/envs/catbook/lib/python3.10/site-packages/anyio/streams/memory.py", line 76, in receive_nowait
    raise WouldBlock
anyio.WouldBlock

During handling of the above exception, another exception occurred:

Traceback (most recent call last):
  File "/Users/andrew/miniconda3/envs/catbook/lib/python3.10/site-packages/starlette/middleware/base.py", line 159, in call_next
    message = await recv_stream.receive()
  File "/Users/andrew/miniconda3/envs/catbook/lib/python3.10/site-packages/anyio/streams/memory.py", line 101, in receive
    raise EndOfStream
anyio.EndOfStream

During handling of the above exception, another exception occurred:

Traceback (most recent call last):
  File "/Users/andrew/miniconda3/envs/catbook/lib/python3.10/site-packages/chromadb/server/fastapi/__init__.py", line 80, in catch_exceptions_middleware
    return await call_next(request)
  File "/Users/andrew/miniconda3/envs/catbook/lib/python3.10/site-packages/starlette/middleware/base.py", line 165, in call_next
    raise app_exc
  File "/Users/andrew/miniconda3/envs/catbook/lib/python3.10/site-packages/starlette/middleware/base.py", line 151, in coro
    await self.app(scope, receive_or_disconnect, send_no_error)
  File "/Users/andrew/miniconda3/envs/catbook/lib/python3.10/site-packages/starlette/middleware/base.py", line 191, in __call__
    response = await self.dispatch_func(request, call_next)
  File "/Users/andrew/miniconda3/envs/catbook/lib/python3.10/site-packages/chromadb/server/fastapi/__init__.py", line 94, in check_http_version_middleware
    return await call_next(request)
  File "/Users/andrew/miniconda3/envs/catbook/lib/python3.10/site-packages/starlette/middleware/base.py", line 165, in call_next
    raise app_exc
  File "/Users/andrew/miniconda3/envs/catbook/lib/python3.10/site-packages/starlette/middleware/base.py", line 151, in coro
    await self.app(scope, receive_or_disconnect, send_no_error)
  File "/Users/andrew/miniconda3/envs/catbook/lib/python3.10/site-packages/starlette/middleware/exceptions.py", line 62, in __call__
    await wrap_app_handling_exceptions(self.app, conn)(scope, receive, send)
  File "/Users/andrew/miniconda3/envs/catbook/lib/python3.10/site-packages/starlette/_exception_handler.py", line 55, in wrapped_app
    raise exc
  File "/Users/andrew/miniconda3/envs/catbook/lib/python3.10/site-packages/starlette/_exception_handler.py", line 44, in wrapped_app
    await app(scope, receive, sender)
  File "/Users/andrew/miniconda3/envs/catbook/lib/python3.10/site-packages/starlette/routing.py", line 746, in __call__
    await route.handle(scope, receive, send)
  File "/Users/andrew/miniconda3/envs/catbook/lib/python3.10/site-packages/starlette/routing.py", line 288, in handle
    await self.app(scope, receive, send)
  File "/Users/andrew/miniconda3/envs/catbook/lib/python3.10/site-packages/starlette/routing.py", line 75, in app
    await wrap_app_handling_exceptions(app, request)(scope, receive, send)
  File "/Users/andrew/miniconda3/envs/catbook/lib/python3.10/site-packages/starlette/_exception_handler.py", line 55, in wrapped_app
    raise exc
  File "/Users/andrew/miniconda3/envs/catbook/lib/python3.10/site-packages/starlette/_exception_handler.py", line 44, in wrapped_app
    await app(scope, receive, sender)
  File "/Users/andrew/miniconda3/envs/catbook/lib/python3.10/site-packages/starlette/routing.py", line 70, in app
    response = await func(request)
  File "/Users/andrew/miniconda3/envs/catbook/lib/python3.10/site-packages/fastapi/routing.py", line 299, in app
    raise e
  File "/Users/andrew/miniconda3/envs/catbook/lib/python3.10/site-packages/fastapi/routing.py", line 294, in app
    raw_response = await run_endpoint_function(
  File "/Users/andrew/miniconda3/envs/catbook/lib/python3.10/site-packages/fastapi/routing.py", line 193, in run_endpoint_function
    return await run_in_threadpool(dependant.call, **values)
  File "/Users/andrew/miniconda3/envs/catbook/lib/python3.10/site-packages/starlette/concurrency.py", line 35, in run_in_threadpool
    return await anyio.to_thread.run_sync(func, *args)
  File "/Users/andrew/miniconda3/envs/catbook/lib/python3.10/site-packages/anyio/to_thread.py", line 28, in run_sync
    return await get_asynclib().run_sync_in_worker_thread(func, *args, cancellable=cancellable,
  File "/Users/andrew/miniconda3/envs/catbook/lib/python3.10/site-packages/anyio/_backends/_asyncio.py", line 818, in run_sync_in_worker_thread
    return await future
  File "/Users/andrew/miniconda3/envs/catbook/lib/python3.10/site-packages/anyio/_backends/_asyncio.py", line 754, in run
    result = context.run(func, *args)
  File "/Users/andrew/miniconda3/envs/catbook/lib/python3.10/site-packages/chromadb/telemetry/opentelemetry/__init__.py", line 127, in wrapper
    return f(*args, **kwargs)
  File "/Users/andrew/miniconda3/envs/catbook/lib/python3.10/site-packages/chromadb/auth/fastapi.py", line 234, in wrapped
    return f(*args, **kwargs)
  File "/Users/andrew/miniconda3/envs/catbook/lib/python3.10/site-packages/chromadb/server/fastapi/__init__.py", line 408, in create_collection
    return self._api.create_collection(
  File "/Users/andrew/miniconda3/envs/catbook/lib/python3.10/site-packages/chromadb/telemetry/opentelemetry/__init__.py", line 127, in wrapper
    return f(*args, **kwargs)
  File "/Users/andrew/miniconda3/envs/catbook/lib/python3.10/site-packages/chromadb/api/segment.py", line 166, in create_collection
    coll, created = self._sysdb.create_collection(
  File "/Users/andrew/miniconda3/envs/catbook/lib/python3.10/site-packages/chromadb/telemetry/opentelemetry/__init__.py", line 127, in wrapper
    return f(*args, **kwargs)
  File "/Users/andrew/miniconda3/envs/catbook/lib/python3.10/site-packages/chromadb/db/mixins/sysdb.py", line 225, in create_collection
    raise UniqueConstraintError(f"Collection {name} already exists")
chromadb.db.base.UniqueConstraintError: Collection my_collection already exists
[32mINFO[0m:     [10-01-2024 20:57:24] ::1:62988 - "POST /api/v1/collections?tenant=default_tenant&database=default_database HTTP/1.1" 500
[32mINFO[0m:     [10-01-2024 20:57:54] ::1:63011 - "POST /api/v1/collections?tenant=default_tenant&database=default_database HTTP/1.1" 200
[31mERROR[0m:    [10-01-2024 20:59:53] Collection catbook-collection already exists
Traceback (most recent call last):
  File "/Users/andrew/miniconda3/envs/catbook/lib/python3.10/site-packages/anyio/streams/memory.py", line 81, in receive
    return self.receive_nowait()
  File "/Users/andrew/miniconda3/envs/catbook/lib/python3.10/site-packages/anyio/streams/memory.py", line 76, in receive_nowait
    raise WouldBlock
anyio.WouldBlock

During handling of the above exception, another exception occurred:

Traceback (most recent call last):
  File "/Users/andrew/miniconda3/envs/catbook/lib/python3.10/site-packages/starlette/middleware/base.py", line 159, in call_next
    message = await recv_stream.receive()
  File "/Users/andrew/miniconda3/envs/catbook/lib/python3.10/site-packages/anyio/streams/memory.py", line 101, in receive
    raise EndOfStream
anyio.EndOfStream

During handling of the above exception, another exception occurred:

Traceback (most recent call last):
  File "/Users/andrew/miniconda3/envs/catbook/lib/python3.10/site-packages/chromadb/server/fastapi/__init__.py", line 80, in catch_exceptions_middleware
    return await call_next(request)
  File "/Users/andrew/miniconda3/envs/catbook/lib/python3.10/site-packages/starlette/middleware/base.py", line 165, in call_next
    raise app_exc
  File "/Users/andrew/miniconda3/envs/catbook/lib/python3.10/site-packages/starlette/middleware/base.py", line 151, in coro
    await self.app(scope, receive_or_disconnect, send_no_error)
  File "/Users/andrew/miniconda3/envs/catbook/lib/python3.10/site-packages/starlette/middleware/base.py", line 191, in __call__
    response = await self.dispatch_func(request, call_next)
  File "/Users/andrew/miniconda3/envs/catbook/lib/python3.10/site-packages/chromadb/server/fastapi/__init__.py", line 94, in check_http_version_middleware
    return await call_next(request)
  File "/Users/andrew/miniconda3/envs/catbook/lib/python3.10/site-packages/starlette/middleware/base.py", line 165, in call_next
    raise app_exc
  File "/Users/andrew/miniconda3/envs/catbook/lib/python3.10/site-packages/starlette/middleware/base.py", line 151, in coro
    await self.app(scope, receive_or_disconnect, send_no_error)
  File "/Users/andrew/miniconda3/envs/catbook/lib/python3.10/site-packages/starlette/middleware/exceptions.py", line 62, in __call__
    await wrap_app_handling_exceptions(self.app, conn)(scope, receive, send)
  File "/Users/andrew/miniconda3/envs/catbook/lib/python3.10/site-packages/starlette/_exception_handler.py", line 55, in wrapped_app
    raise exc
  File "/Users/andrew/miniconda3/envs/catbook/lib/python3.10/site-packages/starlette/_exception_handler.py", line 44, in wrapped_app
    await app(scope, receive, sender)
  File "/Users/andrew/miniconda3/envs/catbook/lib/python3.10/site-packages/starlette/routing.py", line 746, in __call__
    await route.handle(scope, receive, send)
  File "/Users/andrew/miniconda3/envs/catbook/lib/python3.10/site-packages/starlette/routing.py", line 288, in handle
    await self.app(scope, receive, send)
  File "/Users/andrew/miniconda3/envs/catbook/lib/python3.10/site-packages/starlette/routing.py", line 75, in app
    await wrap_app_handling_exceptions(app, request)(scope, receive, send)
  File "/Users/andrew/miniconda3/envs/catbook/lib/python3.10/site-packages/starlette/_exception_handler.py", line 55, in wrapped_app
    raise exc
  File "/Users/andrew/miniconda3/envs/catbook/lib/python3.10/site-packages/starlette/_exception_handler.py", line 44, in wrapped_app
    await app(scope, receive, sender)
  File "/Users/andrew/miniconda3/envs/catbook/lib/python3.10/site-packages/starlette/routing.py", line 70, in app
    response = await func(request)
  File "/Users/andrew/miniconda3/envs/catbook/lib/python3.10/site-packages/fastapi/routing.py", line 299, in app
    raise e
  File "/Users/andrew/miniconda3/envs/catbook/lib/python3.10/site-packages/fastapi/routing.py", line 294, in app
    raw_response = await run_endpoint_function(
  File "/Users/andrew/miniconda3/envs/catbook/lib/python3.10/site-packages/fastapi/routing.py", line 193, in run_endpoint_function
    return await run_in_threadpool(dependant.call, **values)
  File "/Users/andrew/miniconda3/envs/catbook/lib/python3.10/site-packages/starlette/concurrency.py", line 35, in run_in_threadpool
    return await anyio.to_thread.run_sync(func, *args)
  File "/Users/andrew/miniconda3/envs/catbook/lib/python3.10/site-packages/anyio/to_thread.py", line 28, in run_sync
    return await get_asynclib().run_sync_in_worker_thread(func, *args, cancellable=cancellable,
  File "/Users/andrew/miniconda3/envs/catbook/lib/python3.10/site-packages/anyio/_backends/_asyncio.py", line 818, in run_sync_in_worker_thread
    return await future
  File "/Users/andrew/miniconda3/envs/catbook/lib/python3.10/site-packages/anyio/_backends/_asyncio.py", line 754, in run
    result = context.run(func, *args)
  File "/Users/andrew/miniconda3/envs/catbook/lib/python3.10/site-packages/chromadb/telemetry/opentelemetry/__init__.py", line 127, in wrapper
    return f(*args, **kwargs)
  File "/Users/andrew/miniconda3/envs/catbook/lib/python3.10/site-packages/chromadb/auth/fastapi.py", line 234, in wrapped
    return f(*args, **kwargs)
  File "/Users/andrew/miniconda3/envs/catbook/lib/python3.10/site-packages/chromadb/server/fastapi/__init__.py", line 408, in create_collection
    return self._api.create_collection(
  File "/Users/andrew/miniconda3/envs/catbook/lib/python3.10/site-packages/chromadb/telemetry/opentelemetry/__init__.py", line 127, in wrapper
    return f(*args, **kwargs)
  File "/Users/andrew/miniconda3/envs/catbook/lib/python3.10/site-packages/chromadb/api/segment.py", line 166, in create_collection
    coll, created = self._sysdb.create_collection(
  File "/Users/andrew/miniconda3/envs/catbook/lib/python3.10/site-packages/chromadb/telemetry/opentelemetry/__init__.py", line 127, in wrapper
    return f(*args, **kwargs)
  File "/Users/andrew/miniconda3/envs/catbook/lib/python3.10/site-packages/chromadb/db/mixins/sysdb.py", line 225, in create_collection
    raise UniqueConstraintError(f"Collection {name} already exists")
chromadb.db.base.UniqueConstraintError: Collection catbook-collection already exists
[32mINFO[0m:     [10-01-2024 20:59:53] ::1:63107 - "POST /api/v1/collections?tenant=default_tenant&database=default_database HTTP/1.1" 500
[31mERROR[0m:    [10-01-2024 21:00:24] Collection catbook-collection already exists
Traceback (most recent call last):
  File "/Users/andrew/miniconda3/envs/catbook/lib/python3.10/site-packages/anyio/streams/memory.py", line 81, in receive
    return self.receive_nowait()
  File "/Users/andrew/miniconda3/envs/catbook/lib/python3.10/site-packages/anyio/streams/memory.py", line 76, in receive_nowait
    raise WouldBlock
anyio.WouldBlock

During handling of the above exception, another exception occurred:

Traceback (most recent call last):
  File "/Users/andrew/miniconda3/envs/catbook/lib/python3.10/site-packages/starlette/middleware/base.py", line 159, in call_next
    message = await recv_stream.receive()
  File "/Users/andrew/miniconda3/envs/catbook/lib/python3.10/site-packages/anyio/streams/memory.py", line 101, in receive
    raise EndOfStream
anyio.EndOfStream

During handling of the above exception, another exception occurred:

Traceback (most recent call last):
  File "/Users/andrew/miniconda3/envs/catbook/lib/python3.10/site-packages/chromadb/server/fastapi/__init__.py", line 80, in catch_exceptions_middleware
    return await call_next(request)
  File "/Users/andrew/miniconda3/envs/catbook/lib/python3.10/site-packages/starlette/middleware/base.py", line 165, in call_next
    raise app_exc
  File "/Users/andrew/miniconda3/envs/catbook/lib/python3.10/site-packages/starlette/middleware/base.py", line 151, in coro
    await self.app(scope, receive_or_disconnect, send_no_error)
  File "/Users/andrew/miniconda3/envs/catbook/lib/python3.10/site-packages/starlette/middleware/base.py", line 191, in __call__
    response = await self.dispatch_func(request, call_next)
  File "/Users/andrew/miniconda3/envs/catbook/lib/python3.10/site-packages/chromadb/server/fastapi/__init__.py", line 94, in check_http_version_middleware
    return await call_next(request)
  File "/Users/andrew/miniconda3/envs/catbook/lib/python3.10/site-packages/starlette/middleware/base.py", line 165, in call_next
    raise app_exc
  File "/Users/andrew/miniconda3/envs/catbook/lib/python3.10/site-packages/starlette/middleware/base.py", line 151, in coro
    await self.app(scope, receive_or_disconnect, send_no_error)
  File "/Users/andrew/miniconda3/envs/catbook/lib/python3.10/site-packages/starlette/middleware/exceptions.py", line 62, in __call__
    await wrap_app_handling_exceptions(self.app, conn)(scope, receive, send)
  File "/Users/andrew/miniconda3/envs/catbook/lib/python3.10/site-packages/starlette/_exception_handler.py", line 55, in wrapped_app
    raise exc
  File "/Users/andrew/miniconda3/envs/catbook/lib/python3.10/site-packages/starlette/_exception_handler.py", line 44, in wrapped_app
    await app(scope, receive, sender)
  File "/Users/andrew/miniconda3/envs/catbook/lib/python3.10/site-packages/starlette/routing.py", line 746, in __call__
    await route.handle(scope, receive, send)
  File "/Users/andrew/miniconda3/envs/catbook/lib/python3.10/site-packages/starlette/routing.py", line 288, in handle
    await self.app(scope, receive, send)
  File "/Users/andrew/miniconda3/envs/catbook/lib/python3.10/site-packages/starlette/routing.py", line 75, in app
    await wrap_app_handling_exceptions(app, request)(scope, receive, send)
  File "/Users/andrew/miniconda3/envs/catbook/lib/python3.10/site-packages/starlette/_exception_handler.py", line 55, in wrapped_app
    raise exc
  File "/Users/andrew/miniconda3/envs/catbook/lib/python3.10/site-packages/starlette/_exception_handler.py", line 44, in wrapped_app
    await app(scope, receive, sender)
  File "/Users/andrew/miniconda3/envs/catbook/lib/python3.10/site-packages/starlette/routing.py", line 70, in app
    response = await func(request)
  File "/Users/andrew/miniconda3/envs/catbook/lib/python3.10/site-packages/fastapi/routing.py", line 299, in app
    raise e
  File "/Users/andrew/miniconda3/envs/catbook/lib/python3.10/site-packages/fastapi/routing.py", line 294, in app
    raw_response = await run_endpoint_function(
  File "/Users/andrew/miniconda3/envs/catbook/lib/python3.10/site-packages/fastapi/routing.py", line 193, in run_endpoint_function
    return await run_in_threadpool(dependant.call, **values)
  File "/Users/andrew/miniconda3/envs/catbook/lib/python3.10/site-packages/starlette/concurrency.py", line 35, in run_in_threadpool
    return await anyio.to_thread.run_sync(func, *args)
  File "/Users/andrew/miniconda3/envs/catbook/lib/python3.10/site-packages/anyio/to_thread.py", line 28, in run_sync
    return await get_asynclib().run_sync_in_worker_thread(func, *args, cancellable=cancellable,
  File "/Users/andrew/miniconda3/envs/catbook/lib/python3.10/site-packages/anyio/_backends/_asyncio.py", line 818, in run_sync_in_worker_thread
    return await future
  File "/Users/andrew/miniconda3/envs/catbook/lib/python3.10/site-packages/anyio/_backends/_asyncio.py", line 754, in run
    result = context.run(func, *args)
  File "/Users/andrew/miniconda3/envs/catbook/lib/python3.10/site-packages/chromadb/telemetry/opentelemetry/__init__.py", line 127, in wrapper
    return f(*args, **kwargs)
  File "/Users/andrew/miniconda3/envs/catbook/lib/python3.10/site-packages/chromadb/auth/fastapi.py", line 234, in wrapped
    return f(*args, **kwargs)
  File "/Users/andrew/miniconda3/envs/catbook/lib/python3.10/site-packages/chromadb/server/fastapi/__init__.py", line 408, in create_collection
    return self._api.create_collection(
  File "/Users/andrew/miniconda3/envs/catbook/lib/python3.10/site-packages/chromadb/telemetry/opentelemetry/__init__.py", line 127, in wrapper
    return f(*args, **kwargs)
  File "/Users/andrew/miniconda3/envs/catbook/lib/python3.10/site-packages/chromadb/api/segment.py", line 166, in create_collection
    coll, created = self._sysdb.create_collection(
  File "/Users/andrew/miniconda3/envs/catbook/lib/python3.10/site-packages/chromadb/telemetry/opentelemetry/__init__.py", line 127, in wrapper
    return f(*args, **kwargs)
  File "/Users/andrew/miniconda3/envs/catbook/lib/python3.10/site-packages/chromadb/db/mixins/sysdb.py", line 225, in create_collection
    raise UniqueConstraintError(f"Collection {name} already exists")
chromadb.db.base.UniqueConstraintError: Collection catbook-collection already exists
[32mINFO[0m:     [10-01-2024 21:00:24] ::1:63142 - "POST /api/v1/collections?tenant=default_tenant&database=default_database HTTP/1.1" 500
[31mERROR[0m:    [10-01-2024 21:00:27] Collection catbook-collection already exists
Traceback (most recent call last):
  File "/Users/andrew/miniconda3/envs/catbook/lib/python3.10/site-packages/anyio/streams/memory.py", line 81, in receive
    return self.receive_nowait()
  File "/Users/andrew/miniconda3/envs/catbook/lib/python3.10/site-packages/anyio/streams/memory.py", line 76, in receive_nowait
    raise WouldBlock
anyio.WouldBlock

During handling of the above exception, another exception occurred:

Traceback (most recent call last):
  File "/Users/andrew/miniconda3/envs/catbook/lib/python3.10/site-packages/starlette/middleware/base.py", line 159, in call_next
    message = await recv_stream.receive()
  File "/Users/andrew/miniconda3/envs/catbook/lib/python3.10/site-packages/anyio/streams/memory.py", line 101, in receive
    raise EndOfStream
anyio.EndOfStream

During handling of the above exception, another exception occurred:

Traceback (most recent call last):
  File "/Users/andrew/miniconda3/envs/catbook/lib/python3.10/site-packages/chromadb/server/fastapi/__init__.py", line 80, in catch_exceptions_middleware
    return await call_next(request)
  File "/Users/andrew/miniconda3/envs/catbook/lib/python3.10/site-packages/starlette/middleware/base.py", line 165, in call_next
    raise app_exc
  File "/Users/andrew/miniconda3/envs/catbook/lib/python3.10/site-packages/starlette/middleware/base.py", line 151, in coro
    await self.app(scope, receive_or_disconnect, send_no_error)
  File "/Users/andrew/miniconda3/envs/catbook/lib/python3.10/site-packages/starlette/middleware/base.py", line 191, in __call__
    response = await self.dispatch_func(request, call_next)
  File "/Users/andrew/miniconda3/envs/catbook/lib/python3.10/site-packages/chromadb/server/fastapi/__init__.py", line 94, in check_http_version_middleware
    return await call_next(request)
  File "/Users/andrew/miniconda3/envs/catbook/lib/python3.10/site-packages/starlette/middleware/base.py", line 165, in call_next
    raise app_exc
  File "/Users/andrew/miniconda3/envs/catbook/lib/python3.10/site-packages/starlette/middleware/base.py", line 151, in coro
    await self.app(scope, receive_or_disconnect, send_no_error)
  File "/Users/andrew/miniconda3/envs/catbook/lib/python3.10/site-packages/starlette/middleware/exceptions.py", line 62, in __call__
    await wrap_app_handling_exceptions(self.app, conn)(scope, receive, send)
  File "/Users/andrew/miniconda3/envs/catbook/lib/python3.10/site-packages/starlette/_exception_handler.py", line 55, in wrapped_app
    raise exc
  File "/Users/andrew/miniconda3/envs/catbook/lib/python3.10/site-packages/starlette/_exception_handler.py", line 44, in wrapped_app
    await app(scope, receive, sender)
  File "/Users/andrew/miniconda3/envs/catbook/lib/python3.10/site-packages/starlette/routing.py", line 746, in __call__
    await route.handle(scope, receive, send)
  File "/Users/andrew/miniconda3/envs/catbook/lib/python3.10/site-packages/starlette/routing.py", line 288, in handle
    await self.app(scope, receive, send)
  File "/Users/andrew/miniconda3/envs/catbook/lib/python3.10/site-packages/starlette/routing.py", line 75, in app
    await wrap_app_handling_exceptions(app, request)(scope, receive, send)
  File "/Users/andrew/miniconda3/envs/catbook/lib/python3.10/site-packages/starlette/_exception_handler.py", line 55, in wrapped_app
    raise exc
  File "/Users/andrew/miniconda3/envs/catbook/lib/python3.10/site-packages/starlette/_exception_handler.py", line 44, in wrapped_app
    await app(scope, receive, sender)
  File "/Users/andrew/miniconda3/envs/catbook/lib/python3.10/site-packages/starlette/routing.py", line 70, in app
    response = await func(request)
  File "/Users/andrew/miniconda3/envs/catbook/lib/python3.10/site-packages/fastapi/routing.py", line 299, in app
    raise e
  File "/Users/andrew/miniconda3/envs/catbook/lib/python3.10/site-packages/fastapi/routing.py", line 294, in app
    raw_response = await run_endpoint_function(
  File "/Users/andrew/miniconda3/envs/catbook/lib/python3.10/site-packages/fastapi/routing.py", line 193, in run_endpoint_function
    return await run_in_threadpool(dependant.call, **values)
  File "/Users/andrew/miniconda3/envs/catbook/lib/python3.10/site-packages/starlette/concurrency.py", line 35, in run_in_threadpool
    return await anyio.to_thread.run_sync(func, *args)
  File "/Users/andrew/miniconda3/envs/catbook/lib/python3.10/site-packages/anyio/to_thread.py", line 28, in run_sync
    return await get_asynclib().run_sync_in_worker_thread(func, *args, cancellable=cancellable,
  File "/Users/andrew/miniconda3/envs/catbook/lib/python3.10/site-packages/anyio/_backends/_asyncio.py", line 818, in run_sync_in_worker_thread
    return await future
  File "/Users/andrew/miniconda3/envs/catbook/lib/python3.10/site-packages/anyio/_backends/_asyncio.py", line 754, in run
    result = context.run(func, *args)
  File "/Users/andrew/miniconda3/envs/catbook/lib/python3.10/site-packages/chromadb/telemetry/opentelemetry/__init__.py", line 127, in wrapper
    return f(*args, **kwargs)
  File "/Users/andrew/miniconda3/envs/catbook/lib/python3.10/site-packages/chromadb/auth/fastapi.py", line 234, in wrapped
    return f(*args, **kwargs)
  File "/Users/andrew/miniconda3/envs/catbook/lib/python3.10/site-packages/chromadb/server/fastapi/__init__.py", line 408, in create_collection
    return self._api.create_collection(
  File "/Users/andrew/miniconda3/envs/catbook/lib/python3.10/site-packages/chromadb/telemetry/opentelemetry/__init__.py", line 127, in wrapper
    return f(*args, **kwargs)
  File "/Users/andrew/miniconda3/envs/catbook/lib/python3.10/site-packages/chromadb/api/segment.py", line 166, in create_collection
    coll, created = self._sysdb.create_collection(
  File "/Users/andrew/miniconda3/envs/catbook/lib/python3.10/site-packages/chromadb/telemetry/opentelemetry/__init__.py", line 127, in wrapper
    return f(*args, **kwargs)
  File "/Users/andrew/miniconda3/envs/catbook/lib/python3.10/site-packages/chromadb/db/mixins/sysdb.py", line 225, in create_collection
    raise UniqueConstraintError(f"Collection {name} already exists")
chromadb.db.base.UniqueConstraintError: Collection catbook-collection already exists
[32mINFO[0m:     [10-01-2024 21:00:27] ::1:63145 - "POST /api/v1/collections?tenant=default_tenant&database=default_database HTTP/1.1" 500
[31mERROR[0m:    [10-01-2024 21:01:58] Collection catbook-collection already exists
Traceback (most recent call last):
  File "/Users/andrew/miniconda3/envs/catbook/lib/python3.10/site-packages/anyio/streams/memory.py", line 81, in receive
    return self.receive_nowait()
  File "/Users/andrew/miniconda3/envs/catbook/lib/python3.10/site-packages/anyio/streams/memory.py", line 76, in receive_nowait
    raise WouldBlock
anyio.WouldBlock

During handling of the above exception, another exception occurred:

Traceback (most recent call last):
  File "/Users/andrew/miniconda3/envs/catbook/lib/python3.10/site-packages/starlette/middleware/base.py", line 159, in call_next
    message = await recv_stream.receive()
  File "/Users/andrew/miniconda3/envs/catbook/lib/python3.10/site-packages/anyio/streams/memory.py", line 101, in receive
    raise EndOfStream
anyio.EndOfStream

During handling of the above exception, another exception occurred:

Traceback (most recent call last):
  File "/Users/andrew/miniconda3/envs/catbook/lib/python3.10/site-packages/chromadb/server/fastapi/__init__.py", line 80, in catch_exceptions_middleware
    return await call_next(request)
  File "/Users/andrew/miniconda3/envs/catbook/lib/python3.10/site-packages/starlette/middleware/base.py", line 165, in call_next
    raise app_exc
  File "/Users/andrew/miniconda3/envs/catbook/lib/python3.10/site-packages/starlette/middleware/base.py", line 151, in coro
    await self.app(scope, receive_or_disconnect, send_no_error)
  File "/Users/andrew/miniconda3/envs/catbook/lib/python3.10/site-packages/starlette/middleware/base.py", line 191, in __call__
    response = await self.dispatch_func(request, call_next)
  File "/Users/andrew/miniconda3/envs/catbook/lib/python3.10/site-packages/chromadb/server/fastapi/__init__.py", line 94, in check_http_version_middleware
    return await call_next(request)
  File "/Users/andrew/miniconda3/envs/catbook/lib/python3.10/site-packages/starlette/middleware/base.py", line 165, in call_next
    raise app_exc
  File "/Users/andrew/miniconda3/envs/catbook/lib/python3.10/site-packages/starlette/middleware/base.py", line 151, in coro
    await self.app(scope, receive_or_disconnect, send_no_error)
  File "/Users/andrew/miniconda3/envs/catbook/lib/python3.10/site-packages/starlette/middleware/exceptions.py", line 62, in __call__
    await wrap_app_handling_exceptions(self.app, conn)(scope, receive, send)
  File "/Users/andrew/miniconda3/envs/catbook/lib/python3.10/site-packages/starlette/_exception_handler.py", line 55, in wrapped_app
    raise exc
  File "/Users/andrew/miniconda3/envs/catbook/lib/python3.10/site-packages/starlette/_exception_handler.py", line 44, in wrapped_app
    await app(scope, receive, sender)
  File "/Users/andrew/miniconda3/envs/catbook/lib/python3.10/site-packages/starlette/routing.py", line 746, in __call__
    await route.handle(scope, receive, send)
  File "/Users/andrew/miniconda3/envs/catbook/lib/python3.10/site-packages/starlette/routing.py", line 288, in handle
    await self.app(scope, receive, send)
  File "/Users/andrew/miniconda3/envs/catbook/lib/python3.10/site-packages/starlette/routing.py", line 75, in app
    await wrap_app_handling_exceptions(app, request)(scope, receive, send)
  File "/Users/andrew/miniconda3/envs/catbook/lib/python3.10/site-packages/starlette/_exception_handler.py", line 55, in wrapped_app
    raise exc
  File "/Users/andrew/miniconda3/envs/catbook/lib/python3.10/site-packages/starlette/_exception_handler.py", line 44, in wrapped_app
    await app(scope, receive, sender)
  File "/Users/andrew/miniconda3/envs/catbook/lib/python3.10/site-packages/starlette/routing.py", line 70, in app
    response = await func(request)
  File "/Users/andrew/miniconda3/envs/catbook/lib/python3.10/site-packages/fastapi/routing.py", line 299, in app
    raise e
  File "/Users/andrew/miniconda3/envs/catbook/lib/python3.10/site-packages/fastapi/routing.py", line 294, in app
    raw_response = await run_endpoint_function(
  File "/Users/andrew/miniconda3/envs/catbook/lib/python3.10/site-packages/fastapi/routing.py", line 193, in run_endpoint_function
    return await run_in_threadpool(dependant.call, **values)
  File "/Users/andrew/miniconda3/envs/catbook/lib/python3.10/site-packages/starlette/concurrency.py", line 35, in run_in_threadpool
    return await anyio.to_thread.run_sync(func, *args)
  File "/Users/andrew/miniconda3/envs/catbook/lib/python3.10/site-packages/anyio/to_thread.py", line 28, in run_sync
    return await get_asynclib().run_sync_in_worker_thread(func, *args, cancellable=cancellable,
  File "/Users/andrew/miniconda3/envs/catbook/lib/python3.10/site-packages/anyio/_backends/_asyncio.py", line 818, in run_sync_in_worker_thread
    return await future
  File "/Users/andrew/miniconda3/envs/catbook/lib/python3.10/site-packages/anyio/_backends/_asyncio.py", line 754, in run
    result = context.run(func, *args)
  File "/Users/andrew/miniconda3/envs/catbook/lib/python3.10/site-packages/chromadb/telemetry/opentelemetry/__init__.py", line 127, in wrapper
    return f(*args, **kwargs)
  File "/Users/andrew/miniconda3/envs/catbook/lib/python3.10/site-packages/chromadb/auth/fastapi.py", line 234, in wrapped
    return f(*args, **kwargs)
  File "/Users/andrew/miniconda3/envs/catbook/lib/python3.10/site-packages/chromadb/server/fastapi/__init__.py", line 408, in create_collection
    return self._api.create_collection(
  File "/Users/andrew/miniconda3/envs/catbook/lib/python3.10/site-packages/chromadb/telemetry/opentelemetry/__init__.py", line 127, in wrapper
    return f(*args, **kwargs)
  File "/Users/andrew/miniconda3/envs/catbook/lib/python3.10/site-packages/chromadb/api/segment.py", line 166, in create_collection
    coll, created = self._sysdb.create_collection(
  File "/Users/andrew/miniconda3/envs/catbook/lib/python3.10/site-packages/chromadb/telemetry/opentelemetry/__init__.py", line 127, in wrapper
    return f(*args, **kwargs)
  File "/Users/andrew/miniconda3/envs/catbook/lib/python3.10/site-packages/chromadb/db/mixins/sysdb.py", line 225, in create_collection
    raise UniqueConstraintError(f"Collection {name} already exists")
chromadb.db.base.UniqueConstraintError: Collection catbook-collection already exists
[32mINFO[0m:     [10-01-2024 21:01:58] ::1:63210 - "POST /api/v1/collections?tenant=default_tenant&database=default_database HTTP/1.1" 500
[31mERROR[0m:    [10-01-2024 21:03:11] Collection catbook-collection already exists
Traceback (most recent call last):
  File "/Users/andrew/miniconda3/envs/catbook/lib/python3.10/site-packages/anyio/streams/memory.py", line 81, in receive
    return self.receive_nowait()
  File "/Users/andrew/miniconda3/envs/catbook/lib/python3.10/site-packages/anyio/streams/memory.py", line 76, in receive_nowait
    raise WouldBlock
anyio.WouldBlock

During handling of the above exception, another exception occurred:

Traceback (most recent call last):
  File "/Users/andrew/miniconda3/envs/catbook/lib/python3.10/site-packages/starlette/middleware/base.py", line 159, in call_next
    message = await recv_stream.receive()
  File "/Users/andrew/miniconda3/envs/catbook/lib/python3.10/site-packages/anyio/streams/memory.py", line 101, in receive
    raise EndOfStream
anyio.EndOfStream

During handling of the above exception, another exception occurred:

Traceback (most recent call last):
  File "/Users/andrew/miniconda3/envs/catbook/lib/python3.10/site-packages/chromadb/server/fastapi/__init__.py", line 80, in catch_exceptions_middleware
    return await call_next(request)
  File "/Users/andrew/miniconda3/envs/catbook/lib/python3.10/site-packages/starlette/middleware/base.py", line 165, in call_next
    raise app_exc
  File "/Users/andrew/miniconda3/envs/catbook/lib/python3.10/site-packages/starlette/middleware/base.py", line 151, in coro
    await self.app(scope, receive_or_disconnect, send_no_error)
  File "/Users/andrew/miniconda3/envs/catbook/lib/python3.10/site-packages/starlette/middleware/base.py", line 191, in __call__
    response = await self.dispatch_func(request, call_next)
  File "/Users/andrew/miniconda3/envs/catbook/lib/python3.10/site-packages/chromadb/server/fastapi/__init__.py", line 94, in check_http_version_middleware
    return await call_next(request)
  File "/Users/andrew/miniconda3/envs/catbook/lib/python3.10/site-packages/starlette/middleware/base.py", line 165, in call_next
    raise app_exc
  File "/Users/andrew/miniconda3/envs/catbook/lib/python3.10/site-packages/starlette/middleware/base.py", line 151, in coro
    await self.app(scope, receive_or_disconnect, send_no_error)
  File "/Users/andrew/miniconda3/envs/catbook/lib/python3.10/site-packages/starlette/middleware/exceptions.py", line 62, in __call__
    await wrap_app_handling_exceptions(self.app, conn)(scope, receive, send)
  File "/Users/andrew/miniconda3/envs/catbook/lib/python3.10/site-packages/starlette/_exception_handler.py", line 55, in wrapped_app
    raise exc
  File "/Users/andrew/miniconda3/envs/catbook/lib/python3.10/site-packages/starlette/_exception_handler.py", line 44, in wrapped_app
    await app(scope, receive, sender)
  File "/Users/andrew/miniconda3/envs/catbook/lib/python3.10/site-packages/starlette/routing.py", line 746, in __call__
    await route.handle(scope, receive, send)
  File "/Users/andrew/miniconda3/envs/catbook/lib/python3.10/site-packages/starlette/routing.py", line 288, in handle
    await self.app(scope, receive, send)
  File "/Users/andrew/miniconda3/envs/catbook/lib/python3.10/site-packages/starlette/routing.py", line 75, in app
    await wrap_app_handling_exceptions(app, request)(scope, receive, send)
  File "/Users/andrew/miniconda3/envs/catbook/lib/python3.10/site-packages/starlette/_exception_handler.py", line 55, in wrapped_app
    raise exc
  File "/Users/andrew/miniconda3/envs/catbook/lib/python3.10/site-packages/starlette/_exception_handler.py", line 44, in wrapped_app
    await app(scope, receive, sender)
  File "/Users/andrew/miniconda3/envs/catbook/lib/python3.10/site-packages/starlette/routing.py", line 70, in app
    response = await func(request)
  File "/Users/andrew/miniconda3/envs/catbook/lib/python3.10/site-packages/fastapi/routing.py", line 299, in app
    raise e
  File "/Users/andrew/miniconda3/envs/catbook/lib/python3.10/site-packages/fastapi/routing.py", line 294, in app
    raw_response = await run_endpoint_function(
  File "/Users/andrew/miniconda3/envs/catbook/lib/python3.10/site-packages/fastapi/routing.py", line 193, in run_endpoint_function
    return await run_in_threadpool(dependant.call, **values)
  File "/Users/andrew/miniconda3/envs/catbook/lib/python3.10/site-packages/starlette/concurrency.py", line 35, in run_in_threadpool
    return await anyio.to_thread.run_sync(func, *args)
  File "/Users/andrew/miniconda3/envs/catbook/lib/python3.10/site-packages/anyio/to_thread.py", line 28, in run_sync
    return await get_asynclib().run_sync_in_worker_thread(func, *args, cancellable=cancellable,
  File "/Users/andrew/miniconda3/envs/catbook/lib/python3.10/site-packages/anyio/_backends/_asyncio.py", line 818, in run_sync_in_worker_thread
    return await future
  File "/Users/andrew/miniconda3/envs/catbook/lib/python3.10/site-packages/anyio/_backends/_asyncio.py", line 754, in run
    result = context.run(func, *args)
  File "/Users/andrew/miniconda3/envs/catbook/lib/python3.10/site-packages/chromadb/telemetry/opentelemetry/__init__.py", line 127, in wrapper
    return f(*args, **kwargs)
  File "/Users/andrew/miniconda3/envs/catbook/lib/python3.10/site-packages/chromadb/auth/fastapi.py", line 234, in wrapped
    return f(*args, **kwargs)
  File "/Users/andrew/miniconda3/envs/catbook/lib/python3.10/site-packages/chromadb/server/fastapi/__init__.py", line 408, in create_collection
    return self._api.create_collection(
  File "/Users/andrew/miniconda3/envs/catbook/lib/python3.10/site-packages/chromadb/telemetry/opentelemetry/__init__.py", line 127, in wrapper
    return f(*args, **kwargs)
  File "/Users/andrew/miniconda3/envs/catbook/lib/python3.10/site-packages/chromadb/api/segment.py", line 166, in create_collection
    coll, created = self._sysdb.create_collection(
  File "/Users/andrew/miniconda3/envs/catbook/lib/python3.10/site-packages/chromadb/telemetry/opentelemetry/__init__.py", line 127, in wrapper
    return f(*args, **kwargs)
  File "/Users/andrew/miniconda3/envs/catbook/lib/python3.10/site-packages/chromadb/db/mixins/sysdb.py", line 225, in create_collection
    raise UniqueConstraintError(f"Collection {name} already exists")
chromadb.db.base.UniqueConstraintError: Collection catbook-collection already exists
[32mINFO[0m:     [10-01-2024 21:03:11] ::1:63270 - "POST /api/v1/collections?tenant=default_tenant&database=default_database HTTP/1.1" 500
[31mERROR[0m:    [10-01-2024 21:03:19] Collection catbook-collection already exists
Traceback (most recent call last):
  File "/Users/andrew/miniconda3/envs/catbook/lib/python3.10/site-packages/anyio/streams/memory.py", line 81, in receive
    return self.receive_nowait()
  File "/Users/andrew/miniconda3/envs/catbook/lib/python3.10/site-packages/anyio/streams/memory.py", line 76, in receive_nowait
    raise WouldBlock
anyio.WouldBlock

During handling of the above exception, another exception occurred:

Traceback (most recent call last):
  File "/Users/andrew/miniconda3/envs/catbook/lib/python3.10/site-packages/starlette/middleware/base.py", line 159, in call_next
    message = await recv_stream.receive()
  File "/Users/andrew/miniconda3/envs/catbook/lib/python3.10/site-packages/anyio/streams/memory.py", line 101, in receive
    raise EndOfStream
anyio.EndOfStream

During handling of the above exception, another exception occurred:

Traceback (most recent call last):
  File "/Users/andrew/miniconda3/envs/catbook/lib/python3.10/site-packages/chromadb/server/fastapi/__init__.py", line 80, in catch_exceptions_middleware
    return await call_next(request)
  File "/Users/andrew/miniconda3/envs/catbook/lib/python3.10/site-packages/starlette/middleware/base.py", line 165, in call_next
    raise app_exc
  File "/Users/andrew/miniconda3/envs/catbook/lib/python3.10/site-packages/starlette/middleware/base.py", line 151, in coro
    await self.app(scope, receive_or_disconnect, send_no_error)
  File "/Users/andrew/miniconda3/envs/catbook/lib/python3.10/site-packages/starlette/middleware/base.py", line 191, in __call__
    response = await self.dispatch_func(request, call_next)
  File "/Users/andrew/miniconda3/envs/catbook/lib/python3.10/site-packages/chromadb/server/fastapi/__init__.py", line 94, in check_http_version_middleware
    return await call_next(request)
  File "/Users/andrew/miniconda3/envs/catbook/lib/python3.10/site-packages/starlette/middleware/base.py", line 165, in call_next
    raise app_exc
  File "/Users/andrew/miniconda3/envs/catbook/lib/python3.10/site-packages/starlette/middleware/base.py", line 151, in coro
    await self.app(scope, receive_or_disconnect, send_no_error)
  File "/Users/andrew/miniconda3/envs/catbook/lib/python3.10/site-packages/starlette/middleware/exceptions.py", line 62, in __call__
    await wrap_app_handling_exceptions(self.app, conn)(scope, receive, send)
  File "/Users/andrew/miniconda3/envs/catbook/lib/python3.10/site-packages/starlette/_exception_handler.py", line 55, in wrapped_app
    raise exc
  File "/Users/andrew/miniconda3/envs/catbook/lib/python3.10/site-packages/starlette/_exception_handler.py", line 44, in wrapped_app
    await app(scope, receive, sender)
  File "/Users/andrew/miniconda3/envs/catbook/lib/python3.10/site-packages/starlette/routing.py", line 746, in __call__
    await route.handle(scope, receive, send)
  File "/Users/andrew/miniconda3/envs/catbook/lib/python3.10/site-packages/starlette/routing.py", line 288, in handle
    await self.app(scope, receive, send)
  File "/Users/andrew/miniconda3/envs/catbook/lib/python3.10/site-packages/starlette/routing.py", line 75, in app
    await wrap_app_handling_exceptions(app, request)(scope, receive, send)
  File "/Users/andrew/miniconda3/envs/catbook/lib/python3.10/site-packages/starlette/_exception_handler.py", line 55, in wrapped_app
    raise exc
  File "/Users/andrew/miniconda3/envs/catbook/lib/python3.10/site-packages/starlette/_exception_handler.py", line 44, in wrapped_app
    await app(scope, receive, sender)
  File "/Users/andrew/miniconda3/envs/catbook/lib/python3.10/site-packages/starlette/routing.py", line 70, in app
    response = await func(request)
  File "/Users/andrew/miniconda3/envs/catbook/lib/python3.10/site-packages/fastapi/routing.py", line 299, in app
    raise e
  File "/Users/andrew/miniconda3/envs/catbook/lib/python3.10/site-packages/fastapi/routing.py", line 294, in app
    raw_response = await run_endpoint_function(
  File "/Users/andrew/miniconda3/envs/catbook/lib/python3.10/site-packages/fastapi/routing.py", line 193, in run_endpoint_function
    return await run_in_threadpool(dependant.call, **values)
  File "/Users/andrew/miniconda3/envs/catbook/lib/python3.10/site-packages/starlette/concurrency.py", line 35, in run_in_threadpool
    return await anyio.to_thread.run_sync(func, *args)
  File "/Users/andrew/miniconda3/envs/catbook/lib/python3.10/site-packages/anyio/to_thread.py", line 28, in run_sync
    return await get_asynclib().run_sync_in_worker_thread(func, *args, cancellable=cancellable,
  File "/Users/andrew/miniconda3/envs/catbook/lib/python3.10/site-packages/anyio/_backends/_asyncio.py", line 818, in run_sync_in_worker_thread
    return await future
  File "/Users/andrew/miniconda3/envs/catbook/lib/python3.10/site-packages/anyio/_backends/_asyncio.py", line 754, in run
    result = context.run(func, *args)
  File "/Users/andrew/miniconda3/envs/catbook/lib/python3.10/site-packages/chromadb/telemetry/opentelemetry/__init__.py", line 127, in wrapper
    return f(*args, **kwargs)
  File "/Users/andrew/miniconda3/envs/catbook/lib/python3.10/site-packages/chromadb/auth/fastapi.py", line 234, in wrapped
    return f(*args, **kwargs)
  File "/Users/andrew/miniconda3/envs/catbook/lib/python3.10/site-packages/chromadb/server/fastapi/__init__.py", line 408, in create_collection
    return self._api.create_collection(
  File "/Users/andrew/miniconda3/envs/catbook/lib/python3.10/site-packages/chromadb/telemetry/opentelemetry/__init__.py", line 127, in wrapper
    return f(*args, **kwargs)
  File "/Users/andrew/miniconda3/envs/catbook/lib/python3.10/site-packages/chromadb/api/segment.py", line 166, in create_collection
    coll, created = self._sysdb.create_collection(
  File "/Users/andrew/miniconda3/envs/catbook/lib/python3.10/site-packages/chromadb/telemetry/opentelemetry/__init__.py", line 127, in wrapper
    return f(*args, **kwargs)
  File "/Users/andrew/miniconda3/envs/catbook/lib/python3.10/site-packages/chromadb/db/mixins/sysdb.py", line 225, in create_collection
    raise UniqueConstraintError(f"Collection {name} already exists")
chromadb.db.base.UniqueConstraintError: Collection catbook-collection already exists
[32mINFO[0m:     [10-01-2024 21:03:19] ::1:63277 - "POST /api/v1/collections?tenant=default_tenant&database=default_database HTTP/1.1" 500
[31mERROR[0m:    [10-01-2024 21:04:12] Collection catbook-collection already exists
Traceback (most recent call last):
  File "/Users/andrew/miniconda3/envs/catbook/lib/python3.10/site-packages/anyio/streams/memory.py", line 81, in receive
    return self.receive_nowait()
  File "/Users/andrew/miniconda3/envs/catbook/lib/python3.10/site-packages/anyio/streams/memory.py", line 76, in receive_nowait
    raise WouldBlock
anyio.WouldBlock

During handling of the above exception, another exception occurred:

Traceback (most recent call last):
  File "/Users/andrew/miniconda3/envs/catbook/lib/python3.10/site-packages/starlette/middleware/base.py", line 159, in call_next
    message = await recv_stream.receive()
  File "/Users/andrew/miniconda3/envs/catbook/lib/python3.10/site-packages/anyio/streams/memory.py", line 101, in receive
    raise EndOfStream
anyio.EndOfStream

During handling of the above exception, another exception occurred:

Traceback (most recent call last):
  File "/Users/andrew/miniconda3/envs/catbook/lib/python3.10/site-packages/chromadb/server/fastapi/__init__.py", line 80, in catch_exceptions_middleware
    return await call_next(request)
  File "/Users/andrew/miniconda3/envs/catbook/lib/python3.10/site-packages/starlette/middleware/base.py", line 165, in call_next
    raise app_exc
  File "/Users/andrew/miniconda3/envs/catbook/lib/python3.10/site-packages/starlette/middleware/base.py", line 151, in coro
    await self.app(scope, receive_or_disconnect, send_no_error)
  File "/Users/andrew/miniconda3/envs/catbook/lib/python3.10/site-packages/starlette/middleware/base.py", line 191, in __call__
    response = await self.dispatch_func(request, call_next)
  File "/Users/andrew/miniconda3/envs/catbook/lib/python3.10/site-packages/chromadb/server/fastapi/__init__.py", line 94, in check_http_version_middleware
    return await call_next(request)
  File "/Users/andrew/miniconda3/envs/catbook/lib/python3.10/site-packages/starlette/middleware/base.py", line 165, in call_next
    raise app_exc
  File "/Users/andrew/miniconda3/envs/catbook/lib/python3.10/site-packages/starlette/middleware/base.py", line 151, in coro
    await self.app(scope, receive_or_disconnect, send_no_error)
  File "/Users/andrew/miniconda3/envs/catbook/lib/python3.10/site-packages/starlette/middleware/exceptions.py", line 62, in __call__
    await wrap_app_handling_exceptions(self.app, conn)(scope, receive, send)
  File "/Users/andrew/miniconda3/envs/catbook/lib/python3.10/site-packages/starlette/_exception_handler.py", line 55, in wrapped_app
    raise exc
  File "/Users/andrew/miniconda3/envs/catbook/lib/python3.10/site-packages/starlette/_exception_handler.py", line 44, in wrapped_app
    await app(scope, receive, sender)
  File "/Users/andrew/miniconda3/envs/catbook/lib/python3.10/site-packages/starlette/routing.py", line 746, in __call__
    await route.handle(scope, receive, send)
  File "/Users/andrew/miniconda3/envs/catbook/lib/python3.10/site-packages/starlette/routing.py", line 288, in handle
    await self.app(scope, receive, send)
  File "/Users/andrew/miniconda3/envs/catbook/lib/python3.10/site-packages/starlette/routing.py", line 75, in app
    await wrap_app_handling_exceptions(app, request)(scope, receive, send)
  File "/Users/andrew/miniconda3/envs/catbook/lib/python3.10/site-packages/starlette/_exception_handler.py", line 55, in wrapped_app
    raise exc
  File "/Users/andrew/miniconda3/envs/catbook/lib/python3.10/site-packages/starlette/_exception_handler.py", line 44, in wrapped_app
    await app(scope, receive, sender)
  File "/Users/andrew/miniconda3/envs/catbook/lib/python3.10/site-packages/starlette/routing.py", line 70, in app
    response = await func(request)
  File "/Users/andrew/miniconda3/envs/catbook/lib/python3.10/site-packages/fastapi/routing.py", line 299, in app
    raise e
  File "/Users/andrew/miniconda3/envs/catbook/lib/python3.10/site-packages/fastapi/routing.py", line 294, in app
    raw_response = await run_endpoint_function(
  File "/Users/andrew/miniconda3/envs/catbook/lib/python3.10/site-packages/fastapi/routing.py", line 193, in run_endpoint_function
    return await run_in_threadpool(dependant.call, **values)
  File "/Users/andrew/miniconda3/envs/catbook/lib/python3.10/site-packages/starlette/concurrency.py", line 35, in run_in_threadpool
    return await anyio.to_thread.run_sync(func, *args)
  File "/Users/andrew/miniconda3/envs/catbook/lib/python3.10/site-packages/anyio/to_thread.py", line 28, in run_sync
    return await get_asynclib().run_sync_in_worker_thread(func, *args, cancellable=cancellable,
  File "/Users/andrew/miniconda3/envs/catbook/lib/python3.10/site-packages/anyio/_backends/_asyncio.py", line 818, in run_sync_in_worker_thread
    return await future
  File "/Users/andrew/miniconda3/envs/catbook/lib/python3.10/site-packages/anyio/_backends/_asyncio.py", line 754, in run
    result = context.run(func, *args)
  File "/Users/andrew/miniconda3/envs/catbook/lib/python3.10/site-packages/chromadb/telemetry/opentelemetry/__init__.py", line 127, in wrapper
    return f(*args, **kwargs)
  File "/Users/andrew/miniconda3/envs/catbook/lib/python3.10/site-packages/chromadb/auth/fastapi.py", line 234, in wrapped
    return f(*args, **kwargs)
  File "/Users/andrew/miniconda3/envs/catbook/lib/python3.10/site-packages/chromadb/server/fastapi/__init__.py", line 408, in create_collection
    return self._api.create_collection(
  File "/Users/andrew/miniconda3/envs/catbook/lib/python3.10/site-packages/chromadb/telemetry/opentelemetry/__init__.py", line 127, in wrapper
    return f(*args, **kwargs)
  File "/Users/andrew/miniconda3/envs/catbook/lib/python3.10/site-packages/chromadb/api/segment.py", line 166, in create_collection
    coll, created = self._sysdb.create_collection(
  File "/Users/andrew/miniconda3/envs/catbook/lib/python3.10/site-packages/chromadb/telemetry/opentelemetry/__init__.py", line 127, in wrapper
    return f(*args, **kwargs)
  File "/Users/andrew/miniconda3/envs/catbook/lib/python3.10/site-packages/chromadb/db/mixins/sysdb.py", line 225, in create_collection
    raise UniqueConstraintError(f"Collection {name} already exists")
chromadb.db.base.UniqueConstraintError: Collection catbook-collection already exists
[32mINFO[0m:     [10-01-2024 21:04:12] ::1:63324 - "POST /api/v1/collections?tenant=default_tenant&database=default_database HTTP/1.1" 500
[31mERROR[0m:    [10-01-2024 21:04:36] Collection catbook-collection already exists
Traceback (most recent call last):
  File "/Users/andrew/miniconda3/envs/catbook/lib/python3.10/site-packages/anyio/streams/memory.py", line 81, in receive
    return self.receive_nowait()
  File "/Users/andrew/miniconda3/envs/catbook/lib/python3.10/site-packages/anyio/streams/memory.py", line 76, in receive_nowait
    raise WouldBlock
anyio.WouldBlock

During handling of the above exception, another exception occurred:

Traceback (most recent call last):
  File "/Users/andrew/miniconda3/envs/catbook/lib/python3.10/site-packages/starlette/middleware/base.py", line 159, in call_next
    message = await recv_stream.receive()
  File "/Users/andrew/miniconda3/envs/catbook/lib/python3.10/site-packages/anyio/streams/memory.py", line 101, in receive
    raise EndOfStream
anyio.EndOfStream

During handling of the above exception, another exception occurred:

Traceback (most recent call last):
  File "/Users/andrew/miniconda3/envs/catbook/lib/python3.10/site-packages/chromadb/server/fastapi/__init__.py", line 80, in catch_exceptions_middleware
    return await call_next(request)
  File "/Users/andrew/miniconda3/envs/catbook/lib/python3.10/site-packages/starlette/middleware/base.py", line 165, in call_next
    raise app_exc
  File "/Users/andrew/miniconda3/envs/catbook/lib/python3.10/site-packages/starlette/middleware/base.py", line 151, in coro
    await self.app(scope, receive_or_disconnect, send_no_error)
  File "/Users/andrew/miniconda3/envs/catbook/lib/python3.10/site-packages/starlette/middleware/base.py", line 191, in __call__
    response = await self.dispatch_func(request, call_next)
  File "/Users/andrew/miniconda3/envs/catbook/lib/python3.10/site-packages/chromadb/server/fastapi/__init__.py", line 94, in check_http_version_middleware
    return await call_next(request)
  File "/Users/andrew/miniconda3/envs/catbook/lib/python3.10/site-packages/starlette/middleware/base.py", line 165, in call_next
    raise app_exc
  File "/Users/andrew/miniconda3/envs/catbook/lib/python3.10/site-packages/starlette/middleware/base.py", line 151, in coro
    await self.app(scope, receive_or_disconnect, send_no_error)
  File "/Users/andrew/miniconda3/envs/catbook/lib/python3.10/site-packages/starlette/middleware/exceptions.py", line 62, in __call__
    await wrap_app_handling_exceptions(self.app, conn)(scope, receive, send)
  File "/Users/andrew/miniconda3/envs/catbook/lib/python3.10/site-packages/starlette/_exception_handler.py", line 55, in wrapped_app
    raise exc
  File "/Users/andrew/miniconda3/envs/catbook/lib/python3.10/site-packages/starlette/_exception_handler.py", line 44, in wrapped_app
    await app(scope, receive, sender)
  File "/Users/andrew/miniconda3/envs/catbook/lib/python3.10/site-packages/starlette/routing.py", line 746, in __call__
    await route.handle(scope, receive, send)
  File "/Users/andrew/miniconda3/envs/catbook/lib/python3.10/site-packages/starlette/routing.py", line 288, in handle
    await self.app(scope, receive, send)
  File "/Users/andrew/miniconda3/envs/catbook/lib/python3.10/site-packages/starlette/routing.py", line 75, in app
    await wrap_app_handling_exceptions(app, request)(scope, receive, send)
  File "/Users/andrew/miniconda3/envs/catbook/lib/python3.10/site-packages/starlette/_exception_handler.py", line 55, in wrapped_app
    raise exc
  File "/Users/andrew/miniconda3/envs/catbook/lib/python3.10/site-packages/starlette/_exception_handler.py", line 44, in wrapped_app
    await app(scope, receive, sender)
  File "/Users/andrew/miniconda3/envs/catbook/lib/python3.10/site-packages/starlette/routing.py", line 70, in app
    response = await func(request)
  File "/Users/andrew/miniconda3/envs/catbook/lib/python3.10/site-packages/fastapi/routing.py", line 299, in app
    raise e
  File "/Users/andrew/miniconda3/envs/catbook/lib/python3.10/site-packages/fastapi/routing.py", line 294, in app
    raw_response = await run_endpoint_function(
  File "/Users/andrew/miniconda3/envs/catbook/lib/python3.10/site-packages/fastapi/routing.py", line 193, in run_endpoint_function
    return await run_in_threadpool(dependant.call, **values)
  File "/Users/andrew/miniconda3/envs/catbook/lib/python3.10/site-packages/starlette/concurrency.py", line 35, in run_in_threadpool
    return await anyio.to_thread.run_sync(func, *args)
  File "/Users/andrew/miniconda3/envs/catbook/lib/python3.10/site-packages/anyio/to_thread.py", line 28, in run_sync
    return await get_asynclib().run_sync_in_worker_thread(func, *args, cancellable=cancellable,
  File "/Users/andrew/miniconda3/envs/catbook/lib/python3.10/site-packages/anyio/_backends/_asyncio.py", line 818, in run_sync_in_worker_thread
    return await future
  File "/Users/andrew/miniconda3/envs/catbook/lib/python3.10/site-packages/anyio/_backends/_asyncio.py", line 754, in run
    result = context.run(func, *args)
  File "/Users/andrew/miniconda3/envs/catbook/lib/python3.10/site-packages/chromadb/telemetry/opentelemetry/__init__.py", line 127, in wrapper
    return f(*args, **kwargs)
  File "/Users/andrew/miniconda3/envs/catbook/lib/python3.10/site-packages/chromadb/auth/fastapi.py", line 234, in wrapped
    return f(*args, **kwargs)
  File "/Users/andrew/miniconda3/envs/catbook/lib/python3.10/site-packages/chromadb/server/fastapi/__init__.py", line 408, in create_collection
    return self._api.create_collection(
  File "/Users/andrew/miniconda3/envs/catbook/lib/python3.10/site-packages/chromadb/telemetry/opentelemetry/__init__.py", line 127, in wrapper
    return f(*args, **kwargs)
  File "/Users/andrew/miniconda3/envs/catbook/lib/python3.10/site-packages/chromadb/api/segment.py", line 166, in create_collection
    coll, created = self._sysdb.create_collection(
  File "/Users/andrew/miniconda3/envs/catbook/lib/python3.10/site-packages/chromadb/telemetry/opentelemetry/__init__.py", line 127, in wrapper
    return f(*args, **kwargs)
  File "/Users/andrew/miniconda3/envs/catbook/lib/python3.10/site-packages/chromadb/db/mixins/sysdb.py", line 225, in create_collection
    raise UniqueConstraintError(f"Collection {name} already exists")
chromadb.db.base.UniqueConstraintError: Collection catbook-collection already exists
[32mINFO[0m:     [10-01-2024 21:04:36] ::1:63342 - "POST /api/v1/collections?tenant=default_tenant&database=default_database HTTP/1.1" 500
[31mERROR[0m:    [10-01-2024 21:04:53] Collection catbook-collection already exists
Traceback (most recent call last):
  File "/Users/andrew/miniconda3/envs/catbook/lib/python3.10/site-packages/anyio/streams/memory.py", line 81, in receive
    return self.receive_nowait()
  File "/Users/andrew/miniconda3/envs/catbook/lib/python3.10/site-packages/anyio/streams/memory.py", line 76, in receive_nowait
    raise WouldBlock
anyio.WouldBlock

During handling of the above exception, another exception occurred:

Traceback (most recent call last):
  File "/Users/andrew/miniconda3/envs/catbook/lib/python3.10/site-packages/starlette/middleware/base.py", line 159, in call_next
    message = await recv_stream.receive()
  File "/Users/andrew/miniconda3/envs/catbook/lib/python3.10/site-packages/anyio/streams/memory.py", line 101, in receive
    raise EndOfStream
anyio.EndOfStream

During handling of the above exception, another exception occurred:

Traceback (most recent call last):
  File "/Users/andrew/miniconda3/envs/catbook/lib/python3.10/site-packages/chromadb/server/fastapi/__init__.py", line 80, in catch_exceptions_middleware
    return await call_next(request)
  File "/Users/andrew/miniconda3/envs/catbook/lib/python3.10/site-packages/starlette/middleware/base.py", line 165, in call_next
    raise app_exc
  File "/Users/andrew/miniconda3/envs/catbook/lib/python3.10/site-packages/starlette/middleware/base.py", line 151, in coro
    await self.app(scope, receive_or_disconnect, send_no_error)
  File "/Users/andrew/miniconda3/envs/catbook/lib/python3.10/site-packages/starlette/middleware/base.py", line 191, in __call__
    response = await self.dispatch_func(request, call_next)
  File "/Users/andrew/miniconda3/envs/catbook/lib/python3.10/site-packages/chromadb/server/fastapi/__init__.py", line 94, in check_http_version_middleware
    return await call_next(request)
  File "/Users/andrew/miniconda3/envs/catbook/lib/python3.10/site-packages/starlette/middleware/base.py", line 165, in call_next
    raise app_exc
  File "/Users/andrew/miniconda3/envs/catbook/lib/python3.10/site-packages/starlette/middleware/base.py", line 151, in coro
    await self.app(scope, receive_or_disconnect, send_no_error)
  File "/Users/andrew/miniconda3/envs/catbook/lib/python3.10/site-packages/starlette/middleware/exceptions.py", line 62, in __call__
    await wrap_app_handling_exceptions(self.app, conn)(scope, receive, send)
  File "/Users/andrew/miniconda3/envs/catbook/lib/python3.10/site-packages/starlette/_exception_handler.py", line 55, in wrapped_app
    raise exc
  File "/Users/andrew/miniconda3/envs/catbook/lib/python3.10/site-packages/starlette/_exception_handler.py", line 44, in wrapped_app
    await app(scope, receive, sender)
  File "/Users/andrew/miniconda3/envs/catbook/lib/python3.10/site-packages/starlette/routing.py", line 746, in __call__
    await route.handle(scope, receive, send)
  File "/Users/andrew/miniconda3/envs/catbook/lib/python3.10/site-packages/starlette/routing.py", line 288, in handle
    await self.app(scope, receive, send)
  File "/Users/andrew/miniconda3/envs/catbook/lib/python3.10/site-packages/starlette/routing.py", line 75, in app
    await wrap_app_handling_exceptions(app, request)(scope, receive, send)
  File "/Users/andrew/miniconda3/envs/catbook/lib/python3.10/site-packages/starlette/_exception_handler.py", line 55, in wrapped_app
    raise exc
  File "/Users/andrew/miniconda3/envs/catbook/lib/python3.10/site-packages/starlette/_exception_handler.py", line 44, in wrapped_app
    await app(scope, receive, sender)
  File "/Users/andrew/miniconda3/envs/catbook/lib/python3.10/site-packages/starlette/routing.py", line 70, in app
    response = await func(request)
  File "/Users/andrew/miniconda3/envs/catbook/lib/python3.10/site-packages/fastapi/routing.py", line 299, in app
    raise e
  File "/Users/andrew/miniconda3/envs/catbook/lib/python3.10/site-packages/fastapi/routing.py", line 294, in app
    raw_response = await run_endpoint_function(
  File "/Users/andrew/miniconda3/envs/catbook/lib/python3.10/site-packages/fastapi/routing.py", line 193, in run_endpoint_function
    return await run_in_threadpool(dependant.call, **values)
  File "/Users/andrew/miniconda3/envs/catbook/lib/python3.10/site-packages/starlette/concurrency.py", line 35, in run_in_threadpool
    return await anyio.to_thread.run_sync(func, *args)
  File "/Users/andrew/miniconda3/envs/catbook/lib/python3.10/site-packages/anyio/to_thread.py", line 28, in run_sync
    return await get_asynclib().run_sync_in_worker_thread(func, *args, cancellable=cancellable,
  File "/Users/andrew/miniconda3/envs/catbook/lib/python3.10/site-packages/anyio/_backends/_asyncio.py", line 818, in run_sync_in_worker_thread
    return await future
  File "/Users/andrew/miniconda3/envs/catbook/lib/python3.10/site-packages/anyio/_backends/_asyncio.py", line 754, in run
    result = context.run(func, *args)
  File "/Users/andrew/miniconda3/envs/catbook/lib/python3.10/site-packages/chromadb/telemetry/opentelemetry/__init__.py", line 127, in wrapper
    return f(*args, **kwargs)
  File "/Users/andrew/miniconda3/envs/catbook/lib/python3.10/site-packages/chromadb/auth/fastapi.py", line 234, in wrapped
    return f(*args, **kwargs)
  File "/Users/andrew/miniconda3/envs/catbook/lib/python3.10/site-packages/chromadb/server/fastapi/__init__.py", line 408, in create_collection
    return self._api.create_collection(
  File "/Users/andrew/miniconda3/envs/catbook/lib/python3.10/site-packages/chromadb/telemetry/opentelemetry/__init__.py", line 127, in wrapper
    return f(*args, **kwargs)
  File "/Users/andrew/miniconda3/envs/catbook/lib/python3.10/site-packages/chromadb/api/segment.py", line 166, in create_collection
    coll, created = self._sysdb.create_collection(
  File "/Users/andrew/miniconda3/envs/catbook/lib/python3.10/site-packages/chromadb/telemetry/opentelemetry/__init__.py", line 127, in wrapper
    return f(*args, **kwargs)
  File "/Users/andrew/miniconda3/envs/catbook/lib/python3.10/site-packages/chromadb/db/mixins/sysdb.py", line 225, in create_collection
    raise UniqueConstraintError(f"Collection {name} already exists")
chromadb.db.base.UniqueConstraintError: Collection catbook-collection already exists
[32mINFO[0m:     [10-01-2024 21:04:53] ::1:63357 - "POST /api/v1/collections?tenant=default_tenant&database=default_database HTTP/1.1" 500
[32mINFO[0m:     [10-01-2024 21:05:57] ::1:63418 - "GET /api/v1/collections?tenant=default_tenant&database=default_database HTTP/1.1" 200
[32mINFO[0m:     [10-01-2024 21:06:01] ::1:63425 - "GET /api/v1/collections?tenant=default_tenant&database=default_database HTTP/1.1" 200
[32mINFO[0m:     [10-01-2024 21:06:36] ::1:63469 - "GET /api/v1/collections?tenant=default_tenant&database=default_database HTTP/1.1" 200
[32mINFO[0m:     [10-01-2024 21:08:31] ::1:63585 - "POST /api/v1/collections?tenant=default_tenant&database=default_database HTTP/1.1" 200
[32mINFO[0m:     [10-01-2024 21:08:33] ::1:63591 - "POST /api/v1/collections?tenant=default_tenant&database=default_database HTTP/1.1" 200
[32mINFO[0m:     [10-01-2024 21:08:44] ::1:63607 - "POST /api/v1/collections?tenant=default_tenant&database=default_database HTTP/1.1" 200
[32mINFO[0m:     [10-01-2024 21:08:51] ::1:63616 - "POST /api/v1/collections?tenant=default_tenant&database=default_database HTTP/1.1" 200
[32mINFO[0m:     [10-01-2024 21:10:24] ::1:63700 - "POST /api/v1/collections?tenant=default_tenant&database=default_database HTTP/1.1" 200
[32mINFO[0m:     [10-01-2024 21:11:53] ::1:63779 - "POST /api/v1/collections?tenant=default_tenant&database=default_database HTTP/1.1" 200
[32mINFO[0m:     [10-01-2024 21:12:00] ::1:63791 - "POST /api/v1/collections?tenant=default_tenant&database=default_database HTTP/1.1" 200
[32mINFO[0m:     [10-01-2024 21:12:01] ::1:63798 - "POST /api/v1/collections?tenant=default_tenant&database=default_database HTTP/1.1" 200
[32mINFO[0m:     [10-01-2024 21:17:31] ::1:64078 - "POST /api/v1/collections?tenant=default_tenant&database=default_database HTTP/1.1" 200
[32mINFO[0m:     [10-01-2024 21:17:37] ::1:64089 - "POST /api/v1/collections?tenant=default_tenant&database=default_database HTTP/1.1" 200
[32mINFO[0m:     [10-01-2024 21:19:37] ::1:64191 - "POST /api/v1/collections?tenant=default_tenant&database=default_database HTTP/1.1" 200
[32mINFO[0m:     [10-01-2024 21:19:50] ::1:64208 - "POST /api/v1/collections?tenant=default_tenant&database=default_database HTTP/1.1" 200
[32mINFO[0m:     [10-01-2024 21:19:56] ::1:64219 - "POST /api/v1/collections?tenant=default_tenant&database=default_database HTTP/1.1" 200
[32mINFO[0m:     [10-01-2024 21:20:27] ::1:64688 - "POST /api/v1/collections?tenant=default_tenant&database=default_database HTTP/1.1" 200
[32mINFO[0m:     [10-01-2024 21:21:21] ::1:64771 - "POST /api/v1/collections?tenant=default_tenant&database=default_database HTTP/1.1" 200
[32mINFO[0m:     [10-01-2024 21:21:22] ::1:64776 - "POST /api/v1/collections?tenant=default_tenant&database=default_database HTTP/1.1" 200
[32mINFO[0m:     [10-01-2024 21:21:51] ::1:64807 - "POST /api/v1/collections?tenant=default_tenant&database=default_database HTTP/1.1" 200
[32mINFO[0m:     [10-01-2024 21:22:05] ::1:64875 - "POST /api/v1/collections?tenant=default_tenant&database=default_database HTTP/1.1" 200
[32mINFO[0m:     [10-01-2024 21:23:07] ::1:64945 - "POST /api/v1/collections?tenant=default_tenant&database=default_database HTTP/1.1" 200
[32mINFO[0m:     [10-01-2024 21:23:46] ::1:65017 - "POST /api/v1/collections?tenant=default_tenant&database=default_database HTTP/1.1" 200
[32mINFO[0m:     [10-01-2024 21:24:16] ::1:65050 - "POST /api/v1/collections?tenant=default_tenant&database=default_database HTTP/1.1" 200
[32mINFO[0m:     [10-01-2024 21:24:23] ::1:65070 - "POST /api/v1/collections?tenant=default_tenant&database=default_database HTTP/1.1" 200
[32mINFO[0m:     [10-01-2024 21:24:36] ::1:65112 - "POST /api/v1/collections?tenant=default_tenant&database=default_database HTTP/1.1" 200
[32mINFO[0m:     [10-01-2024 21:24:37] ::1:65117 - "POST /api/v1/collections?tenant=default_tenant&database=default_database HTTP/1.1" 200
[32mINFO[0m:     [10-01-2024 21:24:37] ::1:65122 - "POST /api/v1/collections?tenant=default_tenant&database=default_database HTTP/1.1" 200
[32mINFO[0m:     [10-01-2024 21:25:04] ::1:65203 - "POST /api/v1/collections?tenant=default_tenant&database=default_database HTTP/1.1" 200
[32mINFO[0m:     [10-01-2024 21:25:05] ::1:65210 - "POST /api/v1/collections?tenant=default_tenant&database=default_database HTTP/1.1" 200
